<?xml version="1.0"?>
<robot name="lucia">

    <material name="grey">
        <color rgba="0.5 0.5 0.5 1" />
    </material>

    <material name="blue">
        <color rgba="0 0 0.5 1" />
    </material>

   <material name="green">
        <color rgba="0 0.5 0 1" />
    </material>

    <!-- base_footprint (projection of base_link on the ground) -->
    <link name="base_footprint"/>

    <!-- base_link and base_footprint -->
    <joint name="base_joint" type="fixed">
        <parent link="base_footprint"/>
        <child link="base_link"/>
        <origin xyz="0.0 0.0 0.010" rpy="0 0 0"/>
    </joint>

    <link name="base_link">
        <visual>
            <geometry>
                <cylinder radius="0.5" length="1.1" />
            </geometry>
            <origin xyz="0 0 0.0" rpy="0 0 0" />
            <material name="green" />
        </visual>
    </link>

    <!-- lsc_mount and base_link -->
    <joint name="lsc_mount_joint" type="fixed">
        <parent link="base_link"/>
        <child link="lsc_mount"/>
        <origin xyz="0.0 0 -0.25" rpy="0 0 0"/>
    </joint>

    <link name="lsc_mount">
        <visual>
            <geometry>
                <cylinder radius="0.1" length="0.06"/>
            </geometry>
            <origin xyz="0 0 0" rpy="0 0 0" />
            <material name="grey" />
        </visual>
    </link>

    <!-- base_link and laser_front (required for Nav2) -->

    <joint name="laser_front_joint" type="fixed">
        <parent link="lsc_mount"/>
        <child link="laser_front"/>
        <origin xyz="0.5 0 0" rpy="0 0 0"/>
    </joint>

    <link name="laser_front">
        <visual>
            <geometry>
                <cylinder radius="0.1" length="0.06"/>
            </geometry>
            <origin xyz="0 0 0" rpy="0 0 0" />
            <material name="grey" />
        </visual>
    </link>

    <!-- base_link and laser_rear (required for Nav2) -->

    <joint name="laser_rear_joint" type="fixed">
        <parent link="lsc_mount"/>
        <child link="laser_rear"/>
        <origin xyz="-0.5 0 0" rpy="0 0 3.14"/>
    </joint>

    <link name="laser_rear">
        <visual>
            <geometry>
                <cylinder radius="0.1" length="0.06"/>
            </geometry>
            <origin xyz="0 0 0" rpy="0 0 0" />
            <material name="grey" />
        </visual>
    </link>

    <!-- Wheels -->

    <joint name="base_left_wheel_joint" type="continuous">
        <parent link="base_link"/>
        <child link="left_wheel"/>
        <origin xyz="0.0 0.3 -0.5" rpy="0 0 0"/>
        <axis xyz="0 1 0"/>
    </joint>

    <link name="left_wheel">
        <visual>
            <geometry>
                <cylinder radius="0.2" length="0.1"/>
            </geometry>
            <origin xyz="0 0 0" rpy="1.57 0 0" />
            <material name="grey" />
        </visual>
    </link>

    <joint name="base_right_wheel_joint" type="continuous">
        <parent link="base_link"/>
        <child link="right_wheel"/>
        <origin xyz="0.0 -0.3 -0.5" rpy="0 0 0"/>
        <axis xyz="0 1 0"/>
    </joint>

    <link name="right_wheel">
        <visual>
            <geometry>
                <cylinder radius="0.2" length="0.1"/>
            </geometry>
            <origin xyz="0 0 0" rpy="1.57 0 0" />
            <material name="grey" />
        </visual>
    </link>

</robot>
